Workbook

Sheet anagrafica
F5: BUSINESS MODEL
G6: PIANIFICAZIONE PER 2025-2026-2027
G10: Azienda: | H10: Bomè S.P.A.
G11: P.IVA: | H11: 00369120225
G12: Settore: | H12: Produzione di prodotti alimentari a base di carne (Ateco C10.13)
D31: LABORATORIO DI PIANIFICAZIONE FINANZIARIA
D32: Docente: | E32: Laura Maran | G32: A.A: | H32: 2025-26
D34: Studente: | E34: Box Alif Mahajan Fuhad

Sheet calcs →

Sheet REVENUE MODEL
B2: Tabella 1: Prezzi di vendita e volumi ipotetici per 2024 su base del bilancio consuntivo | F2: expand for details ↓ | H2: Tabella 2A: Prospettive di crescita dei ricavi e volumi per mix prodotti | L2: expand for details ↓ | Q2: Tabella 1: Prezzi di vendita e volumi ipotetici per 2024 su base del bilancio consuntivo | U2: expand for details ↓
F3: + | L3: + | V3: +
B4: Spiegazione: | C4: Partito dal fatturato per il 2024 come base dei ricavi. Ottenuti i ricavi di linea moltiplicando il fatturato totale per il valore percentuale di categoria. Coeficiente ottenuto sulla base dei fatturati nazionali per rispettive categorie da ASSICA. Maggiori dettagli su B. linea prodotti Bomè. Si è calcolato il prezzo medio di vendita sulla base di prodotti del simile livello, inteso come qualità , produttore e zona geografica e dati pubblicamente disponibili. Visibile su sheet - B. calcolo prezzi medi di vend | H4: Spiegazione: | I4: Dato il fatturato del 2024. Si proietta la crescita negli anni 2025-26-27 utilizzando il tasso di crescita annuale dei ricavi. In assenza di dati previsionali tale tasso è stato individuato effettuando una regressione lineare sulla base dei precedenti 5 anni. I Fatturati previsti annuali sono stati divisi per le rispettive categorie di prodotto usando lo stesso coeficiente individuato nel 2024, ipotizzando stablità dei coeficienti e crescita proporzionata per ciascuna linea di prodotto. Il calcolo dei prezzi di vendita è stato più avanzato, basato su tassi inflazionistici e dati previsionali sulla crescita dei prezzi degli ingredienti, visibile con maggiore dettaglio su B. calcolo prezzi medi di vend. | Q4: Spiegazione:
B5: input: | C5: Fatturato totale del 2024; coefficienti qta per cat. Prodotto; Prezzi medi per categorie; | H5: input: | I5: tasso di crescita annuale; Fatturato 2024; Prezzi medi per categrie di prodotto; coeficienti fattoriali per categorie di prodotto; | Q5: input: | R5: Fatturato 2024; coeficienti fattoriali per categorie di prodotto; Prezzi medi per categorie di prodotto 2024;
B6: output: | C6: Quantità venduta per categorie di prodotto | H6: output: | I6: Ricavi totali per 25-26-27; Ricavi per linee; Quantità di kg venduto per categorie di prodotto; | Q6: output: | R6: Ricavi per linee di prodotto; Quantità di kg venduto per categorie di prodotto 2024.;
B8: MIX PRODOTTI | D8: anno | H8: MIX PRODOTTI | J8: anno | Q8: MIX PRODOTTI | S8: anno
D9: 2024 | J9: 2025 | K9: 2026 | L9: 2027 | S9: 2024
B10: Linea Carne Salada | H10: Linea A - Carne Salada | Q10: Linea Carne Salada
C11: prezzo di vendita [€/kg] | D11: 36.08 | I11: prezzo di vendita [€/kg] | J11: ='B. linea prodotti Bomè'!J121 -> 37.243472 | K11: ='B. linea prodotti Bomè'!K121 -> 38.708555 | L11: ='B. linea prodotti Bomè'!L121 -> 39.996002 | R11: prezzo di vendita [€/kg] | S11: 36.08
C12: quantità [kg] | D12: =D13/D11 -> 44339.106 | I12: quantità [kg] | J12: =J13/J11 -> 44874.012 | K12: =K13/K11 -> 45105.519 | L12: =L13/L11 -> 45604.916 | R12: quantità [kg] | S12: =S13/S11 -> 44339.106
B13: Totale ricavi Linea A | D13: =D34*0.074534161 -> 1599754.9 | H13: Totale ricavi Linea A | J13: =0.074534161*J$34 -> 1671264 | K13: =0.074534161*K$34 -> 1745969.5 | L13: =0.074534161*L$34 -> 1824014.3 | Q13: Totale ricavi Linea A | S13: =S34*0.074534161 -> 1599754.9
B15: Linea Speck | H15: Linea B - Speck | Q15: Linea Speck
C16: prezzo di vendita [€/kg] | D16: 35 | I16: prezzo di vendita [€/kg] | J16: ='B. linea prodotti Bomè'!J125 -> 35.679266 | K16: ='B. linea prodotti Bomè'!K125 -> 36.62157 | L16: ='B. linea prodotti Bomè'!L125 -> 37.368943 | R16: prezzo di vendita [€/kg] | S16: 35
C17: quantità [kg] | D17: =D18/D16 -> 55229.636 | I17: quantità [kg] | J17: =J18/J16 -> 56599.931 | K17: =K18/K16 -> 57608.485 | L17: =L18/L16 -> 58979.922 | R17: quantità [kg] | S17: =S18/S16 -> 55229.636
B18: Totale ricavi Linea B | D18: =0.090062112*D34 -> 1933037.2 | H18: Totale ricavi Linea B | J18: =0.090062112*J$34 -> 2019444 | K18: =0.090062112*K$34 -> 2109713.2 | L18: =0.090062112*L$34 -> 2204017.3 | Q18: Totale ricavi Linea B | S18: =0.090062112*S34 -> 1933037.2
B20: Linea Grasso e Lardo | H20: Linea C - Grasso e Lardo | Q20: Linea Grasso e Lardo
C21: prezzo di vendita [€/kg] | D21: 35.88 | I21: prezzo di vendita [€/kg] | J21: ='B. linea prodotti Bomè'!J122 -> 36.66848 | K21: ='B. linea prodotti Bomè'!K122 -> 37.731717 | L21: ='B. linea prodotti Bomè'!L122 -> 38.598731 | R21: prezzo di vendita [€/kg] | S21: 35.88
C22: quantità [kg] | D22: =D23/D21 -> 70594.909 | I22: quantità [kg] | J22: =J23/J21 -> 72164.649 | K22: =K23/K21 -> 73265.994 | L22: =L23/L21 -> 74821.701 | R22: quantità [kg] | S22: =S23/S21 -> 70594.909
B23: Totale ricavi Linea C | D23: =0.118012422*D34 -> 2532945.3 | H23: Totale ricavi Linea C | J23: =0.118012422*J$34 -> 2646168 | K23: =0.118012422*K$34 -> 2764451.7 | L23: =0.118012422*L$34 -> 2888022.7 | Q23: Totale ricavi Linea C | S23: =0.118012422*S34 -> 2532945.3
B25: Linea Salumi cotti | H25: Linea D - Salumi cotti | Q25: Linea Salumi cotti
C26: prezzo di vendita [€/kg] | D26: 28.83 | I26: prezzo di vendita [€/kg] | J26: ='B. linea prodotti Bomè'!J124 -> 29.540523 | K26: ='B. linea prodotti Bomè'!K124 -> 30.476486 | L26: ='B. linea prodotti Bomè'!L124 -> 31.258232 | R26: prezzo di vendita [€/kg] | S26: 28.83
C27: quantità [kg] | D27: =D28/D26 -> 358368.05 | I27: quantità [kg] | J27: =J28/J26 -> 365382.16 | K27: =K28/K26 -> 369991.9 | L27: =L28/L26 -> 376863.69 | R27: quantità [kg] | S27: =S28/S26 -> 358368.05
B28: Totale ricavi Linea D | D28: =0.48136646*D34 -> 10331751 | H28: Totale ricavi Linea D | J28: =0.48136646*J$34 -> 10793580 | K28: =0.48136646*K$34 -> 11276053 | L28: =0.48136646*L$34 -> 11780093 | Q28: Totale ricavi Linea D | S28: =0.48136646*S34 -> 10331751
B30: Linea Prosciutto alternativo | H30: Linea E - Prosciutto alternativo | Q30: Linea Prosciutto alternativo
C31: prezzo di vendita [€/kg] | D31: 34.47 | I31: prezzo di vendita [€/kg] | J31: ='B. linea prodotti Bomè'!I123 -> 34.47 | K31: ='B. linea prodotti Bomè'!J123 -> 35.593848 | L31: ='B. linea prodotti Bomè'!K123 -> 37.00682 | R31: prezzo di vendita [€/kg] | S31: 34.47
C32: quantità [kg] | D32: =D33/D31 -> 146965.21 | I32: quantità [kg] | J32: =J33/J31 -> 153534.55 | K32: =K33/K31 -> 155333.12 | L32: =L33/L31 -> 156080.56 | R32: quantità [kg] | S32: =S33/S31 -> 146965.21
B33: Totale ricavi Linea E | D33: =0.236024845*D34 -> 5065890.7 | H33: Totale ricavi Linea E | J33: =0.236024845*J$34 -> 5292336 | K33: =0.236024845*K$34 -> 5528903.4 | L33: =0.236024845*L$34 -> 5776045.4 | Q33: Totale ricavi Linea E | S33: =0.236024845*S34 -> 5065890.7
B34: TOTALE RICAVI | D34: 21463379 | H34: TOTALE RICAVI | J34: =S34*(1+M37) -> 22422792 | K34: =J34*(1+M37) -> 23425091 | L34: =K34*(1+M37) -> 24472192 | Q34: TOTALE RICAVI | S34: 21463379
L37: Tasso di crescita annuale dei ricavi previsto: | M37: 0.0447
H39: Ottenuto tramite simple linear regression dei fatturati nazionali dal 2020-2024; Maggiori dettagli su B. linea prodotti Bomè;
H40: Si utilizza questo valore considerandolo più conservativo rispetto al tasso di crescita previsto di +5,7%; presentato a pagina 93 del documento "Assica: Rapporto annuale 2024"
H45: Tabella 2B: Prospettive di crescita dei volumi con valori percentuale rispetto al totale del prodotto | L45: expand for details ↓
L46: +
H47: Spiegazione: | I47: Calcolato le percentuali di volume da produrre rispetto al totale per ciascuna categoria di prodotto per ciascun anno.
H48: input: | I48: Quantità di volume venduto per prodotto 25-26-27;
H49: output: | I49: Percentuale di volume per linea rispetto al totale 25-26-27;
H51: MIX PRODOTTI | J51: anno
J52: 2025 | K52: 2026 | L52: 2027
H54: Linea A - Carne Salada | J54: =J55/J$68 -> 0.064794842 | K54: =K55/K$68 -> 0.06431655 | L54: =L55/L$68 -> 0.064020307
I55: quantità [kg] | J55: =J12 -> 44874.012 | K55: =K12 -> 45105.519 | L55: =L12 -> 45604.916
...

Sheet COSTI DI GESTIONE & BEP
B2: Tabella 3: Costi di gestione dettagliati per 2024-25-26-27 | E2: expand for details ↓ | H2: expand for details → | M2: Tabella 4: Punto di pareggio per fatturato, volume, margine di sicurezza e indice di flessibilità | P2: expand for details ↓
E3: + | J3: + | P3: +
B4: Spiegazione: | C4: Individuate varie voci di costi rispetto al bilancio consuntivo del 2024. Ciascuna voce ha avuto progressione di crescita/diminuzione o stabilità rispetto ai fattori presi in considerazione, visibile espandendo il banner laterale alla destra della tabella. | M4: Spiegazione: | N4: Individuazione del punto di pareggio rispetto al fatturato e rispetto al volume. Considerate le parti di costo variabile, differenziandolo dal ricavo si ottiene il margine di contribuzione. Mc/Ricavi da margine di contribuzione unitario. BEP è CF/MdC%.
B5: input: | C5: variabili varie; | M5: input: | N5: ricavi, costi variabili, costi totali
B6: output: | C6: costi di gestione; | M6: output: | N6: margine di contribuzione; costi fissi; BEP; indici di flessibilità; MdS;
B8: COSTI DI GESTIONE | C8: tipo | D8: 2024 | E8: 2025 | F8: 2026 | G8: 2027 | J8: dettagli | M8: PUNTO DI PAREGGIO DEL FATTURATO | N8: 2025 | O8: 2026 | P8: 2027
B9: Acquisto materie prime | C9: var. | D9: 14699595 | E9: =D9+3.52%*D9 -> 15217021 | F9: =E9+3.52%*E9 -> 15752660 | G9: =F9+3.52%*F9 -> 16307154 | J9: Spese di acquisto per materie prime, crescita prevista del 3,5% annuale, rispettando le proiezioni di ASSICA | M9: Ricavi | N9: ='REVENUE MODEL'!J34 -> 22422792 | O9: ='REVENUE MODEL'!K34 -> 23425091 | P9: ='REVENUE MODEL'!L34 -> 24472192
B10: var. rimanenze | C10: var. | D10: =-CCN!C8 -> 431532 | J10: var rimanenze ignote e molto variabili, non considerate. Si valutano le rimanenze medie in CCNO | M10: Totale costi variabili | N10: =E9+E23+E26+E33+E34+E35 -> 16975741 | O10: =F9+F23+F26+F33+F34+F35 -> 17627516 | P10: =G9+G23+G26+G33+G34+G35 -> 18269795
B11: Costo del venduto | D11: =SUM(D9:D10) -> 15131127 | E11: =SUM(E9:E9) -> 15217021 | F11: =SUM(F9:F9) -> 15752660 | G11: =SUM(G9:G9) -> 16307154
M12: Margine di contribuzione | N12: =N9-N10 -> 5447051.4 | O12: =O9-O10 -> 5797575.3 | P12: =P9-P10 -> 6202397.1
B13: Salari e stipendi | C13: fisso | D13: =HR!E20 -> 1114481 | E13: =HR!F20 -> 1194598.9 | F13: =HR!G20 -> 1224812.2 | G13: =HR!H20 -> 1277755.8 | J13: Spese per salari visibile in modo dettagliato sullo sheet - HR; dettagliato sulla base di numeri di dipendenti, tipo di profilo lavorativo. | M13: Margine di contribuzione in % | N13: =N12/N9 -> 0.24292476 | O13: =O12/O9 -> 0.24749425 | P13: =P12/P9 -> 0.25344673
B14: Oneri sociali | C14: fisso | D14: =HR!O7 -> 304319 | E14: =HR!P7 -> 330903.91 | F14: =HR!Q7 -> 339272.97 | G14: =HR!R7 -> 353938.35 | J14: visibile in modo dettagliato sullo sheet - HR;
B15: TFR | C15: fisso | D15: =34063+HR!H70+HR!H71 -> 79658 | E15: =HR!P8 -> 78592.036 | F15: =HR!Q8 -> 80579.747 | G15: =HR!R8 -> 84062.88 | J15: visibile in modo dettagliato sullo sheet - HR; | M15: Costi fissi | N15: =E14+E21+E27+E28+E29+E37+E41+E43+E45+E50+E30+E31+E32+E44 -> 939333.91 | O15: =F14+F21+F27+F28+F29+F37+F41+F43+F45+F50+F30+F31+F32+F44 -> 958405.07 | P15: =G14+G21+G27+G28+G29+G37+G41+G43+G45+G50+G30+G31+G32+G44 -> 984200.75
B16: Costi del personale | D16: =SUM(D13:D15) -> 1498458 | E16: =SUM(E13:E15) -> 1604094.9 | F16: =SUM(F13:F15) -> 1644664.9 | G16: =SUM(G13:G15) -> 1715757 | J16: Totale sommando le voci inerenti precedenti. | M16: Costi di manodopera (compreso TFR) | N16: =E13+E15 -> 1273191 | O16: =F13+F15 -> 1305391.9 | P16: =G13+G15 -> 1361818.7
M17: Costi di sviluppo | N17: =E24+E25 -> 332790.4 | O17: =F24+F25 -> 343625.52 | P17: =G24+G25 -> 357338.6
B18: Amministratori (5) | C18: fisso | D18: =HR!E29+HR!E30 -> 170000 | E18: =HR!F29+HR!F30 -> 172000 | F18: =HR!G29+HR!G30 -> 174000 | G18: =HR!H29+HR!H30 -> 176000 | J18: visibile in modo dettagliato sullo sheet - HR; | M18: Ammortamenti | N18: =incidenze!D16+incidenze!D18 -> 799296.26 | O18: =incidenze!E16+incidenze!E18 -> 749688.49 | P18: =incidenze!F16+incidenze!F18 -> 730241.24
B19: Sindaci (5) | C19: fisso | D19: =HR!E31+HR!E32 -> 122000 | E19: =HR!F31+HR!F32 -> 122000 | F19: =HR!G31+HR!G32 -> 122000 | G19: =HR!H31+HR!H32 -> 122000 | J19: visibile in modo dettagliato sullo sheet - HR; | M19: Totale costi fissi | N19: =SUM(N15:N18) -> 3344611.6 | O19: =SUM(O15:O18) -> 3357111 | P19: =SUM(P15:P18) -> 3433599.3
B20: Spese per collaboratori | C20: fisso | D20: =HR!E27 -> 54900 | E20: =HR!F27 -> 56600 | F20: =HR!G27 -> 56600 | G20: =HR!H27 -> 56600 | J20: visibile in modo dettagliato sullo sheet - HR;
B21: Servizi: amministratori-consulenti-servizi tecnici | D21: =SUM(D18:D20) -> 346900 | E21: =SUM(E18:E20) -> 350600 | F21: =SUM(F18:F20) -> 352600 | G21: =SUM(G18:G20) -> 354600 | J21: Totale sommando le voci inerenti precedenti. | M21: BEP Fatturato (CF/MDC%) | N21: =N19/N13 -> 13768096 | O21: =O19/O13 -> 13564400 | P21: =P19/P13 -> 13547617
B23: provvigioni ed oneri concessi | C23: var. | D23: =0.3*0.1*D9 -> 440987.85 | E23: =0.3*0.1*E9 -> 456510.62 | F23: =0.3*0.1*F9 -> 472579.8 | G23: =0.3*0.1*G9 -> 489214.61 | J23: Provvigioni concesse ipotizzando che il 30% del sales sia di generazione da parte di salespeople, il compenso è pari al 10% del lead generato per l'intermediazione.
B24: diritti d'autore, R&D, royalties, brevetti,costi di licenze export, certificazioni | C24: fisso | D24: 285349.92 | E24: 285349.92 | F24: 285349.92 | G24: 285349.92 | J24: Spese/budget costante per questa voce.
B25: mostre, fiere, viaggi | C25: fisso | D25: =2354.6+122+4842+14442+20000 -> 41760.6 | E25: =20000+27440.48 -> 47440.48 | F25: =38275.6+20000 -> 58275.6 | G25: =51988.68+20000 -> 71988.68 | J25: Si procede con un crescente investimento nel processo di marketing del proprio marchio, questo viene effettuato intensificando la propria presenza nei expo/fiere di settore a livello nazionale e internazionale. Dettagli in fondo pagina | M25: INDICE DI FLESSIBILITA | N25: 2025 | O25: 2026 | P25: 2027
B26: spese doganali import-export-trasporti | C26: var. | D26: =0.05*D9 -> 734979.75 | E26: =0.05*E9 -> 760851.04 | F26: =0.05*F9 -> 787632.99 | G26: =0.05*G9 -> 815357.68 | J26: Ipotizzate spese doganali pari al 5% del fatturato. Non include VAT. Include spese doganali, trasporti e relativa gestione. Impossibile quantificare, dipende da: prodotto x paese di export/import x spese di trasporto x assicurazioni | M26: Indice di flessibilità (CV tot/CF tot) | N26: =N10/N19 -> 5.0755492 | O26: =O10/O19 -> 5.2507992 | P26: =P10/P19 -> 5.3208875
B27: spese per consulenza commerciale | C27: fisso | D27: =300*12 -> 3600 | E27: =300*12 -> 3600 | F27: =300*12 -> 3600 | G27: =300*12 -> 3600 | J27: Consulenza commerciale per 300 mensili IVA esclusa. Costo tipico di consulenza. | M27: %CV su CT | N27: =N10/(N10+N19) -> 0.83540583 | O27: =O10/(O10+O19) -> 0.84002046 | P27: =P10/(P10+P19) -> 0.84179437
B28: spese per consulenza tributaria/legale | C28: fisso | D28: =3000*1.5 -> 4500 | E28: =3000*1.5 -> 4500 | F28: =3000*1.5 -> 4500 | G28: =3000*1.5 -> 4500 | J28: Spese annuali ricorrenti per servizio di un studio legale. | M28: %CF su CT | N28: =N19/(N19+N10) -> 0.16459417 | O28: =O19/(O19+O10) -> 0.15997954 | P28: =P19/(P19+P10) -> 0.15820563
B29: spese di auditing | C29: fisso | D29: 10000 | E29: 10000 | F29: 10000 | G29: 10000 | J29: Spesa di auditing tecnico/sanitario/amministrativo.
B30: spese per servizi di laboratorio avanzato | C30: fisso | D30: 4000 | E30: =D30 -> 4000 | F30: =E30 -> 4000 | G30: =F30 -> 4000 | J30: Spese di ricerca relative all'analisi dei prodotti alimentari, servizio outsourced a terzi.
B31: spese abbonamenti software professionali e gestionali | C31: fisso | D31: 8000 | E31: 8000 | F31: 8000 | G31: 8000 | J31: Spese ipotetiche di gestionale custom, SaaS.
B32: spese servizi di manutenzione | C32: fisso | D32: 30000 | E32: 30000 | F32: =E32 -> 30000 | G32: =F32 -> 30000 | J32: Spese di manutenzione ipotetiche relative a macchinari, strumenti, auto.
B33: spese gestione rifiuti | C33: var. | D33: =0.25*85*('REVENUE MODEL'!S12+'REVENUE MODEL'!S17+'REVENUE MODEL'!S22+'REVENUE MODEL'!S27+'REVENUE MODEL'!S32)/1000 -> 14354.309 | E33: =0.25*85*('REVENUE MODEL'!J12+'REVENUE MODEL'!J17+'REVENUE MODEL'!J22+'REVENUE MODEL'!J27+'REVENUE MODEL'!J32)/1000 -> 14716.8 | F33: =0.25*85*('REVENUE MODEL'!K12+'REVENUE MODEL'!K17+'REVENUE MODEL'!K22+'REVENUE MODEL'!K27+'REVENUE MODEL'!K32)/1000 -> 14902.732 | G33: =0.25*85*('REVENUE MODEL'!L12+'REVENUE MODEL'!L17+'REVENUE MODEL'!L22+'REVENUE MODEL'!L27+'REVENUE MODEL'!L32)/1000 -> 15137.454 | J33: Spese di gestione rifiuti, calcolato tramite 85 euro * tonnelata *25% di scarto rispetto a materie prime acquistate.(ossa, grassi, membrane etc.) | M33: PUNTO DI PAREGGIO OPERATIVO IN VOLUME | N33: 2025 | O33: 2026 | P33: 2027
B34: spese gestione idrica | C34: var. | D34: =0.02*6000*1*0.16*0.001*('REVENUE MODEL'!S12+'REVENUE MODEL'!S17+'REVENUE MODEL'!S22+'REVENUE MODEL'!S27+'REVENUE MODEL'!S32) -> 12969.541 | E34: =0.02*6000*1*0.16*0.001*('REVENUE MODEL'!J12+'REVENUE MODEL'!J17+'REVENUE MODEL'!J22+'REVENUE MODEL'!J27+'REVENUE MODEL'!J32) -> 13297.062 | F34: =0.02*6000*1*0.16*0.001*('REVENUE MODEL'!K12+'REVENUE MODEL'!K17+'REVENUE MODEL'!K22+'REVENUE MODEL'!K27+'REVENUE MODEL'!K32) -> 13465.056 | G34: =0.02*6000*1*0.16*0.001*('REVENUE MODEL'!L12+'REVENUE MODEL'!L17+'REVENUE MODEL'!L22+'REVENUE MODEL'!L27+'REVENUE MODEL'!L32) -> 13677.135 | J34: Spese di gestione idrica, 0,16 euro k-litro consumo di 6 litri per chilo di prodotto in output. | M34: Quantità in kg | N34: ='REVENUE MODEL'!J12+'REVENUE MODEL'!J17+'REVENUE MODEL'!J22+'REVENUE MODEL'!J27+'REVENUE MODEL'!J32 -> 692555.3 | O34: ='REVENUE MODEL'!K12+'REVENUE MODEL'!K17+'REVENUE MODEL'!K22+'REVENUE MODEL'!K27+'REVENUE MODEL'!K32 -> 701305.02 | P34: ='REVENUE MODEL'!L12+'REVENUE MODEL'!L17+'REVENUE MODEL'!L22+'REVENUE MODEL'!L27+'REVENUE MODEL'!L32 -> 712350.79
B35: spese gestione elettrica | C35: var. | D35: =2.36862669519772E-06*0.262937559*('REVENUE MODEL'!S12+'REVENUE MODEL'!S17+'REVENUE MODEL'!S22+'REVENUE MODEL'!S27+'REVENUE MODEL'!S32)*1000000 -> 420700.09 | E35: =1000000*2.36862669519772E-06*0.312937559*('REVENUE MODEL'!J12+'REVENUE MODEL'!J17+'REVENUE MODEL'!J22+'REVENUE MODEL'!J27+'REVENUE MODEL'!J32) -> 513344.33 | F35: =1000000*2.36862669519772E-06*0.352937559*('REVENUE MODEL'!K12+'REVENUE MODEL'!K17+'REVENUE MODEL'!K22+'REVENUE MODEL'!K27+'REVENUE MODEL'!K32) -> 586275.1 | G35: =1000000*2.36862669519772E-06*0.372937559*('REVENUE MODEL'!L12+'REVENUE MODEL'!L17+'REVENUE MODEL'!L22+'REVENUE MODEL'!L27+'REVENUE MODEL'!L32) -> 629254.97 | J35: Spese di gestione elettrica, 1,6 GW/h a 0,26 kW/h euro. Sulla base di dimensione del punto produttivo e consumo medio per tipo di impresa. Prezzo medio per val di Ledro. | M35: Ricavo unitario ponderato | N35: ='REVENUE MODEL'!J11*('REVENUE MODEL'!J13/'REVENUE MODEL'!J34)+'REVENUE MODEL'!J16*('REVENUE MODEL'!J18/'REVENUE MODEL'!J34)+'REVENUE MODEL'!J21*('REVENUE MODEL'!J23/'REVENUE MODEL'!J34)+'REVENUE MODEL'!J26*('REVENUE MODEL'!J28/'REVENUE MODEL'!J34)+'REVENUE MODEL'!J31*('REVENUE MODEL'!J33/'REVENUE MODEL'!J34) -> 32.67219 | O35: ='REVENUE MODEL'!K11*('REVENUE MODEL'!K13/'REVENUE MODEL'!K34)+'REVENUE MODEL'!K16*('REVENUE MODEL'!K18/'REVENUE MODEL'!K34)+'REVENUE MODEL'!K21*('REVENUE MODEL'!K23/'REVENUE MODEL'!K34)+'REVENUE MODEL'!K26*('REVENUE MODEL'!K28/'REVENUE MODEL'!K34)+'REVENUE MODEL'!K31*('REVENUE MODEL'!K33/'REVENUE MODEL'!K34) -> 33.707527 | P35: ='REVENUE MODEL'!L11*('REVENUE MODEL'!L13/'REVENUE MODEL'!L34)+'REVENUE MODEL'!L16*('REVENUE MODEL'!L18/'REVENUE MODEL'!L34)+'REVENUE MODEL'!L21*('REVENUE MODEL'!L23/'REVENUE MODEL'!L34)+'REVENUE MODEL'!L26*('REVENUE MODEL'!L28/'REVENUE MODEL'!L34)+'REVENUE MODEL'!L31*('REVENUE MODEL'!L33/'REVENUE MODEL'!L34) -> 34.682918
B36: spese per servizi: altro | C36: fisso | D36: 44123.94 | J36: Altra spesa | M36: Costo variabile unitario | N36: =N10/('REVENUE MODEL'!J12+'REVENUE MODEL'!J17+'REVENUE MODEL'!J22+'REVENUE MODEL'!J27+'REVENUE MODEL'!J32) -> 24.511747 | O36: =O10/('REVENUE MODEL'!K12+'REVENUE MODEL'!K17+'REVENUE MODEL'!K22+'REVENUE MODEL'!K27+'REVENUE MODEL'!K32) -> 25.135305 | P36: =P10/('REVENUE MODEL'!L12+'REVENUE MODEL'!L17+'REVENUE MODEL'!L22+'REVENUE MODEL'!L27+'REVENUE MODEL'!L32) -> 25.647189
B37: spese di pulizia | C37: fisso | D37: 20000 | E37: =D37 -> 20000 | F37: =E37 -> 20000 | G37: =F37 -> 20000 | J37: Spese di pulizia annuali outsourced. Prezzo alto perché pulizia frequente, professionale e inclusa sanitarizzazione | M37: Margine di contribuzione unitario | N37: =N35-N36 -> 8.1604431 | O37: =O35-O36 -> 8.5722225 | P37: =P35-P36 -> 9.0357287
B38: Servizi: costi servizi commerciali | D38: =SUM(D23:D37) -> 2075326 | E38: =SUM(E23:E37) -> 2171610.3 | F38: =SUM(F23:F37) -> 2298581.2 | G38: =SUM(G23:G37) -> 2400080.4
B39: Servizi totali | D39: =D21+D38 -> 2422226 | E39: =E38+E21 -> 2522210.3 | F39: =F38+F21 -> 2651181.2 | G39: =G38+G21 -> 2754680.4 | M39: BEP in volume (kg) (CF/MDCu) | N39: =N19/N37 -> 409856.61 | O39: =O19/O37 -> 391626.67 | P39: =P19/P37 -> 380002.47
B41: Godimento di beni terzi | C41: fisso | D41: 117380 | E41: =D41*1.05 -> 123249 | F41: =E41*1.05 -> 129411.45 | G41: =F41*1.05 -> 135882.02
B43: budget cancelleria varia, inchiostro stampanti, fogli | C43: fisso | D43: =50*12 -> 600 | E43: =D43 -> 600 | F43: =E43 -> 600 | G43: =F43 -> 600 | J43: Budget di cancelleria annuale, 3 uffici per tot 600 euro. | M43: MARGINE DI SICUREZZA | N43: 2025 | O43: 2026 | P43: 2027
B44: altri costi, includendo imposte non sul reddito | C44: fisso | D44: =52056-(D43+D45) -> 27886 | E44: =D44*1.0447 -> 29132.504 | F44: =1.0447*E44 -> 30434.727 | G44: =1.0447*F44 -> 31795.159 | J44: Spese di imposte extra-reddito e altre spese | M44: MDS assoluto
B45: assicurazioni | C45: fisso | D45: =6000+6000+(119*30)+8000 -> 23570 | E45: =D45*1.05 -> 24748.5 | F45: =E45*1.05 -> 25985.925 | G45: =F45*1.05 -> 27285.221 | J45: Spesa di assicurazione calcolata con dettagli, crescente al 5% annuale. | M45: +Ricavi effettivi | N45: ='REVENUE MODEL'!J34 -> 22422792 | O45: ='REVENUE MODEL'!K34 -> 23425091 | P45: ='REVENUE MODEL'!L34 -> 24472192
...

Sheet HR
B2: Tabella 5: Costi per risorse umane interne ed esterne all'azienda | H2: expand for details ↓ | L2: Tabella 6: Altri costi per risorse umane | Q2: expand for details ↓
H3: + | Q3: +
B4: Spiegazione: | C4: Proiezione dei costi di risorse umane per il 2025, 2026 e 2027 partendo da valori del 2024 | L4: Spiegazione: | M4: Rendiconto delle altre spese per dipendenti
B6: COSTI PER RISORSE UMANE | D6: qta | E6: 2024 | F6: 2025 | G6: 2026 | H6: 2027 | L6: ALTRE SPESE PER DIPENDENTI | O6: 2024 | P6: 2025 | Q6: 2026 | R6: 2027
B7: =E122 -> Responsabile di pianificazione | D7: =D122 -> 1 | F7: =F129 -> 39840 | G7: =K129 -> 40812 | H7: =P129 -> 41412 | L7: Oneri sociali | O7: 304319 | P7: =O20 -> 330903.91 | Q7: =P20 -> 339272.97 | R7: =Q20 -> 353938.35
B8: =E123 -> Responsabile alimentare | D8: =D123 -> 1 | F8: =H129 -> 27780 | G8: =M129 -> 28548 | H8: =R129 -> 29040 | L8: TFR | O8: 34063 | P8: =O21 -> 78592.036 | Q8: =P21 -> 80579.747 | R8: =Q21 -> 84062.88
B9: =E387 -> Responsabile commerciale | D9: =D387 -> 1 | F9: =H393 -> 61560 | G9: =M393 -> 63312 | H9: =R393 -> 64440
B10: =E430 -> Responsabile finanziario | D10: =D430 -> 1 | F10: =F441 -> 55776 | G10: =I441 -> 57136.8 | H10: =L441 -> 57976.8
B11: =E474 -> Responsabile esecutivo | D11: =D474 -> 1 | F11: =F485 -> 56767.2 | G11: =I485 -> 58447.2 | H11: =L485 -> 59556
B12: =E166 -> Operaio | D12: =D166 -> 11 | F12: =F173 -> 247896 | G12: =K173 -> 254100 | H12: =P173 -> 258324
B13: =E167 -> Operai con uso di strumenti tecnici | D13: =D167 -> 5 | F13: =H173 -> 127680 | G13: =M173 -> 131040 | H13: =R173 -> 133320
B14: =E210 -> Addetto al magazzino | D14: =D210 -> 4 | F14: =F217 -> 89184 | G14: =K217 -> 91008 | H14: =P217 -> 106656
B15: =E211 -> Camionisti | D15: =D211 -> 2 | F15: =H217 -> 46056 | G15: =M217 -> 46992 | H15: =R217 -> 58080
B16: =E254 -> Impiegato tecnico | D16: =D254 -> 2 | F16: =G261 -> 51072 | G16: =J261 -> 52416 | H16: =M261 -> 53328
B17: =E298 -> Impiegato tecnico-informatico | D17: =D298 -> 1 | F17: =G305 -> 27780 | G17: =J305 -> 28548 | H17: =M305 -> 29040
B18: =E342 -> Impiegato amministrativo-contabile | D18: =D342 -> 2 | F18: =G349 -> 48072 | G18: =J349 -> 49320 | H18: =M349 -> 50160 | L18: RENDICONTO COSTI RISORSE UMANE SULLA BASE DEL PROFILO | O18: 2025 | P18: 2026 | Q18: 2027
B19: =E386 -> Agente commerciale | D19: =D386 -> 1 | F19: =F393 -> 25536 | G19: =K393 -> 26208 | H19: =P393 -> 26664 | L19: RAL | O19: =(I129+I173+I217+G261+G305+G349+I393+F441+F485)*N27 -> 1194598.9 | P19: =(N129+N173+N217+J261+J305+J349+N393+I441+I485)*N27 -> 1224812.2 | Q19: =(S129+S173+S217+M261+M305+M349+S393+L441+L485)*N27 -> 1277755.8
B20: Dipendenti | D20: =SUM(D7:D19) -> 33 | E20: =H67 -> 1114481 | F20: =SUM(F7:F19)*N27 -> 1194598.9 | G20: =SUM(G7:G19)*N27 -> 1224812.2 | H20: =SUM(H7:H19)*N27 -> 1277755.8 | L20: oneri sociali | O20: =(I130+I174+I218+G262+G306+G350+I394+G438+G482)*N27 -> 330903.91 | P20: =(N130+N174+N218+J262+J306+J350+N394+J438+J482)*N27 -> 339272.97 | Q20: =(S130+S174+S218+M262+M306+M350+S394+M438+M482)*N27 -> 353938.35
L21: TFR | O21: =(I131+I175+I219+G263+G307+G351+I395+G439+G483)*N27 -> 78592.036 | P21: =(N131+N175+N219+J263+J307+J351+N395+J439+J483)*N27 -> 80579.747 | Q21: =(S131+S175+S219+M263+M307+M351+S395+M439+M483)*N27 -> 84062.88
B22: RSPP | D22: 1 | E22: =D22*200*1.22*12*1.5 -> 4392 | F22: =E22 -> 4392 | G22: =F22 -> 4392 | H22: =G22 -> 4392 | L22: costi accessori | O22: =(I132+I176+I220+G264+G308+G352+I396+G440+G484)*N27 -> 5972.9947 | P22: =(N132+N176+N220+J264+J308+J352+N396+J440+J484)*N27 -> 6124.0608 | Q22: =(S132+S176+S220+M264+M308+M352+S396+M440+M484)*N27 -> 6388.7789
B23: Tecnologo | D23: 1 | E23: =600*1.22*12*1.5 -> 13176 | F23: =E23 -> 13176 | G23: =F23 -> 13176 | H23: =G23 -> 13176 | L23: Totale | O23: =SUM(O19:O22) -> 1610067.9 | P23: =SUM(P19:P22) -> 1650788.9 | Q23: =SUM(Q19:Q22) -> 1722145.8
B24: consulente HACCP | D24: 1 | E24: =D24*(450*1.22*12*1.5) -> 9882 | F24: =E24 -> 9882 | G24: =F24 -> 9882 | H24: =G24 -> 9882
B25: Studio legale | D25: 1 | E25: =10000*1.22*D25*1.5 -> 18300 | F25: 20000 | G25: =F25 -> 20000 | H25: =G25 -> 20000 | L25: Acconti IRPEF per conto dipendenti | O25: =TAX!M33 -> 166339.5 | P25: =TAX!N33 -> 165911.11 | Q25: =TAX!O33 -> 174286.37
B26: Studio commerciale | D26: 1 | E26: =5000*1.22*1.5 -> 9150 | F26: =E26 -> 9150 | G26: =F26 -> 9150 | H26: =G26 -> 9150 | L26: Debito vs erario in bilancio | O26: =(1/12)*O25 -> 13861.625 | P26: =(1/12)*P25 -> 13825.925 | Q26: =(1/12)*Q25 -> 14523.864
B27: Collaboratori | D27: =SUM(D22:D26) -> 5 | E27: =SUM(E22:E26) -> 54900 | F27: =SUM(F22:F26) -> 56600 | G27: =SUM(G22:G26) -> 56600 | H27: =SUM(H22:H26) -> 56600 | L27: coeficiente di maggiorazione e altro complessivi di premi: | N27: 1.32
L28: usato per avere volume salari simile a quelli in bilancio dato che i valori ccnl sono minimi indicativi senza contrattazione datore-dipendente
B29: Presidente del Cda (F. Bomè) | D29: 1 | E29: =12*D29*E51+20000 -> 20000 | F29: =E29+2000 -> 22000 | G29: =F29+2000 -> 24000 | H29: =G29+2000 -> 26000
B30: unità Consiglio di amministrazione | D30: 5 | E30: =D30*30000 -> 150000 | F30: =E30 -> 150000 | G30: =F30 -> 150000 | H30: =G30 -> 150000 | L30: Debito vs erario in bilancio: l'ultima mensilità non viene pagata a chiusura di conti dato che viene pagata entro il 16 di gennaio
B31: presidente del colleggio sindacale | D31: 1 | E31: 26000 | F31: =E31 -> 26000 | G31: =F31 -> 26000 | H31: =G31 -> 26000
B32: unità sindaci | D32: 4 | E32: =D32*24000 -> 96000 | F32: =E32 -> 96000 | G32: =F32 -> 96000 | H32: =G32 -> 96000
B33: Amministratori e Sindaci | D33: =SUM(D29:D32) -> 11 | E33: =SUM(E29:E32) -> 292000 | F33: =SUM(F29:F32) -> 294000 | G33: =SUM(G29:G32) -> 296000 | H33: =SUM(H29:H32) -> 298000
B34: Totale | D34: =D33+D27+D20 -> 49 | E34: =E33+E27+E20 -> 1461381 | F34: =F33+F27+F20 -> 1545198.9 | G34: =G33+G27+G20 -> 1577412.2 | H34: =H33+H27+H20 -> 1632355.8
B37: Proiezioni spese per dipendenti BT
B38: al 2024 sono presenti complessivamente 30 + 2 dipendenti | E38: su base di bilancio AIDA
B39: Nel 2025 si sostituisce un OSA, uscito nel 2024 | E39: su base di bilancio AIDA, e pagina recruiting sul sito aziendale nel 2025
B40: per il 2026 | E40: si ipotizza rimane invariato
B41: per il 2027 | E41: si ipotizza rimane invariato
B43: Le assunzioni sul numero di dipendenti sono fatti sulla base delle foto disponibili sul sito aziendale, sulle immagini e dimensione del sito produttivo e dal numero di auto presenti e chiaramente inerenti all'impresa produttiva.
B50: SPESE PER COLLABORATORI
B52: RSPP | C52: https://www.adecco.com/it-it/candidati/il-lavoro-che-cambia/rspp-cosa-fa | E52: =E22 -> 4392
...

Sheet INV
B2: Tabella 7: Spese di investimento e immobilizzazioni per 25-26-27 | H2: expand for details ↓
H3: +
B4: Spiegazione: | C4: Individuate rispettive voci di investimento rispetto al bilancio consuntivo del 2024. Si scompongono gli investimenti in immobilizzazioni per individuare gli ammortamenti annuali e verificare se le aliquote soiano corrette.In questo modo si calcolano gli ammortamenti futuri. Successivamente si cerca di calcolare gli investimenti storici e in base agli ammortamenti i fondi ammortamento e i numeri di ammortamenti effettuati e rimanenti per ciascuna immobilizzazione.
B7: SPESE DI INVESTIMENTO | C7: 2022 | D7: 2023 | E7: 2024 | F7: 2025 | G7: 2026 | H7: 2027
B8: Diritti brevetti industriali | C8: 130172 | D8: 97381 | E8: 64590 | F8: =N46 -> 35088 | G8: =SUM(N85:N86) -> 992 | H8: =SUM(O85:O86) -> 0
B9: Concessioni, Licenze | C9: 9545 | D9: 8999 | E9: 8453 | F9: =M87 -> 7907 | G9: =N87 -> 7361 | H9: =O87 -> 6815
B10: Altre immobilizzazioni immateriali | C10: 0 | D10: 0 | E10: 16480 | F10: =M88 -> 14832 | G10: =N88 -> 13184 | H10: =O88 -> 11536
B11: Totale investimenti immateriali | C11: =SUM(C8:C10) -> 139717 | D11: =SUM(D8:D10) -> 106380 | E11: =SUM(E8:E10) -> 89523 | F11: =SUM(F8:F10) -> 57827 | G11: =SUM(G8:G10) -> 21537 | H11: =SUM(H8:H10) -> 18351
B14: Terreni e fabbricati | C14: 6543383 | D14: 6328571 | E14: 6069102 | F14: =N56 -> 5796679.2 | G14: =O56 -> 5524256.4 | H14: =P56 -> 5251833.7
B15: Impianti | C15: 2352511 | D15: 2137598 | E15: 1774810 | F15: =N57 -> 1834142.7 | G15: =O57 -> 1409009.1 | H15: =P57 -> 1003322.8
B16: Attrezzature industriali | C16: 184756 | D16: 187192 | E16: 197170 | F16: =N58 -> 168713.53 | G16: =O58 -> 140257.05 | H16: =P58 -> 111800.58
B17: Altri beni immobilizzati | C17: 312178 | D17: 244518 | E17: 177873 | F17: =N59 -> 156391.32 | G17: =O59 -> 134909.64 | H17: =P59 -> 113427.96
B18: Immobilizzazioni in corso | C18: 23700 | D18: 119891 | E18: 475770 | F18: 0 | G18: 0 | H18: 0
B19: Totale investimenti materiali | C19: =SUM(C14:C18) -> 9416528 | D19: =SUM(D14:D18) -> 9017770 | E19: =SUM(E14:E18) -> 8694725 | F19: =SUM(F14:F18) -> 7955926.7 | G19: =SUM(G14:G18) -> 7208432.2 | H19: =SUM(H14:H18) -> 6480385
B22: Partecipazioni | C22: 58702 | D22: =C22 -> 58702 | E22: =D22 -> 58702 | F22: =M126 -> 58702 | G22: =N126 -> 58702 | H22: =O126 -> 58702
B23: Totale investimenti finanziari | C23: =SUM(C22) -> 58702 | D23: =SUM(D22) -> 58702 | E23: =SUM(E22) -> 58702 | F23: =SUM(F22) -> 58702 | G23: =SUM(G22) -> 58702 | H23: =SUM(H22) -> 58702
B26: Ammto immobilizzazioni immateriali | C26: 37282 | D26: 33337 | E26: =SUM(K85:K88) -> 37282 | F26: =SUM(Q85:Q88) -> 36290 | G26: =SUM(R85:R88) -> 2194 | H26: =SUM(S85:S88) -> 2194
B27: Ammto immobilizzazioni materiali | C27: 822987 | D27: 866491 | E27: 879520 | F27: =SUM(Q91:Q95)+SUM(Q98:Q104)+SUM(Q107:Q114)+SUM(Q117:Q121) -> 763006.26 | G27: =SUM(R91:R95)+SUM(R98:R104)+SUM(R107:R114)+SUM(R117:R121) -> 747494.49 | H27: =SUM(S91:S95)+SUM(S98:S104)+SUM(S107:S114)+SUM(S117:S121) -> 728047.24
B28: Totale ammortamenti | C28: =SUM(C26:C27) -> 860269 | D28: =D27+D26 -> 899828 | E28: =E27+E26 -> 916802 | F28: =F27+F26 -> 799296.26 | G28: =G27+G26 -> 749688.49 | H28: =H27+H26 -> 730241.24
B36: PROCESSO DI ANALISI INVESTIMENTI IN IMMOBILIZZAZIONI
L38: Tabella 7A: PROIEZIONI VOCI DI BILANCIO RELATIVE ALLE IMMOBILIZZAZIONI PER IL 2025/26/27
L39: RENDICONTO RISPETTO ALLE ELABORAZIONI PRESENTI IN SEGUITO
B41: BILANCIO CONSUNTIVO | C41: 2024 | D41: 2023 | E41: 2022 | F41: 2021 | G41: 2020 | H41: 2019 | I41: 2018 | J41: 2017 | L41: PROIEZIONE IMMOBILIZZAZIONI | N41: 2025 | O41: 2026 | P41: 2027
B42: B. TOTALE IMMOBILIZZAZIONI sep.ind. Di quelle conc. In loc. Finanz. | C42: 8842950 | D42: 9182852 | E42: 9614947 | F42: 9565702 | G42: 7073181 | H42: 2616289 | I42: 1201123 | J42: 908499 | L42: =B42 -> B. TOTALE IMMOBILIZZAZIONI sep.ind. Di quelle conc. In loc. Finanz. | N42: =N43+N54+N63 -> 8072455.7 | O42: =O43+O54+O63 -> 7288671.2 | P42: =P43+P54+P63 -> 6557438
B43: B.I. TOTALE IMMOB. IMMATERIALI | C43: 89523 | D43: 106380 | E43: 139717 | F43: 76490 | G43: 33453 | H43: 7543 | I43: 0 | J43: 1977 | L43: =B43 -> B.I. TOTALE IMMOB. IMMATERIALI | N43: =SUM(N44:N52) -> 57827 | O43: =SUM(O44:O52) -> 21537 | P43: =SUM(P44:P52) -> 18351
B44: B.I.1. Costi Impianto e ampl. | C44: 0 | D44: 0 | E44: 0 | F44: 0 | G44: 0 | H44: 0 | I44: 0 | J44: 0 | L44: =B44 -> B.I.1. Costi Impianto e ampl. | N44: 0 | O44: 0 | P44: 0
B45: B.I.2. Costi ricerca e pubb. | C45: 0 | D45: 0 | E45: 0 | F45: 0 | G45: 0 | H45: 0 | I45: 0 | J45: 0 | L45: =B45 -> B.I.2. Costi ricerca e pubb. | N45: 0 | O45: 0 | P45: 0
B46: B.I.3. Diritti brevetto ind. | C46: 64590 | D46: 97381 | E46: 130172 | F46: 3968 | G46: 4960 | H46: 0 | I46: 0 | J46: 0 | L46: =B46 -> B.I.3. Diritti brevetto ind. | N46: =C46-SUM(M85:M86) -> 35088 | O46: =N46-K86 -> 992 | P46: 0
B47: B.I.4. Concessioni, licenze | C47: 8453 | D47: 8999 | E47: 9545 | F47: 0 | G47: 0 | H47: 0 | I47: 0 | J47: 0 | L47: =B47 -> B.I.4. Concessioni, licenze | N47: =C47-Q87 -> 7907 | O47: =N47-R87 -> 7361 | P47: =O47-S87 -> 6815
B48: B.I.5. Avviamento/Differenza di consolidamento | C48: 0 | D48: 0 | E48: 0 | F48: 0 | G48: 0 | H48: 0 | I48: 0 | J48: 0 | L48: =B48 -> B.I.5. Avviamento/Differenza di consolidamento | N48: 0 | O48: 0 | P48: 0
B49: di cui: Avviamento | C49: 0 | D49: 0 | E49: 0 | F49: 0 | G49: 0 | H49: 0 | I49: 0 | J49: 0 | L49: =B49 -> di cui: Avviamento | N49: 0 | O49: 0 | P49: 0
B50: B.I.6. Imm. in corso | C50: 0 | D50: 0 | E50: 0 | F50: 67622 | G50: 28493 | H50: 7543 | I50: 0 | J50: 0 | L50: =B50 -> B.I.6. Imm. in corso | N50: 0 | O50: 0 | P50: 0
B51: B.I.7. Altre immobiliz. Immateriali | C51: 16480 | D51: 0 | E51: 0 | F51: 4900 | G51: 0 | H51: 0 | I51: 0 | J51: 1977 | L51: =B51 -> B.I.7. Altre immobiliz. Immateriali | N51: =C51-Q88 -> 14832 | O51: =N51-R88 -> 13184 | P51: =O51-S88 -> 11536
B52: Fondo amm.to Immob. Immateriali | C52: n.d. | D52: n.d. | E52: n.d. | F52: n.d. | G52: n.d. | H52: n.d. | I52: n.d. | J52: n.d. | L52: =B52 -> Fondo amm.to Immob. Immateriali | N52: n.d. | O52: n.d. | P52: n.d.
L53: =B53 -> 0
B54: B.II. TOTALE IMMOB. MATERIALI | C54: 8694725 | D54: 9017770 | E54: 9416528 | F54: 9430510 | G54: 7025024 | H54: 2594042 | I54: 1186419 | J54: 891818 | L54: =B54 -> B.II. TOTALE IMMOB. MATERIALI | N54: =SUM(N55:N61) -> 7955926.7 | O54: =SUM(O55:O61) -> 7208432.2 | P54: =SUM(P55:P61) -> 6480385
B55: di cui: Beni materiali concessi in locazione finanziaria | C55: n.d. | D55: n.d. | E55: n.d. | F55: n.d. | G55: n.d. | H55: n.d. | I55: n.d. | J55: n.d. | L55: =B55 -> di cui: Beni materiali concessi in locazione finanziaria | N55: n.d. | O55: =N55 -> n.d. | P55: =O55 -> n.d.
B56: B.II.1. Terreni e fabbricati | C56: 6069102 | D56: 6328571 | E56: 6543383 | F56: 6374984 | G56: 396319 | H56: 412628 | I56: 418736 | J56: 324645 | L56: =B56 -> B.II.1. Terreni e fabbricati | N56: =C56-SUM(Q91:Q95) -> 5796679.2 | O56: =N56-SUM(R91:R95) -> 5524256.4 | P56: =O56-SUM(S91:S95) -> 5251833.7
B57: B.II.2. Impianti | C57: 1774810 | D57: 2137598 | E57: 2352511 | F57: 2232169 | G57: 1801043 | H57: 258024 | I57: 302043 | J57: 336024 | L57: =B57 -> B.II.2. Impianti | N57: =C57-SUM(Q99:Q103)+U103 -> 1834142.7 | O57: =N57-SUM(R98:R104) -> 1409009.1 | P57: =O57-SUM(S98:S104) -> 1003322.8
B58: B.II.3. Attrez. industriali | C58: 197170 | D58: 187192 | E58: 184756 | F58: 168289 | G58: 141111 | H58: 110856 | I58: 130147 | J58: 133231 | L58: =B58 -> B.II.3. Attrez. industriali | N58: =C58-SUM(Q107:Q114) -> 168713.53 | O58: =N58-SUM(R107:R114) -> 140257.05 | P58: =O58-SUM(S107:S114) -> 111800.58
...

Sheet CCN
B2: Tabella 10A: Proiezione CCN operativo | F2: expand for details ↓
B4: Spiegazione: | C4: Calcolo delle varie voci del CCN operativo, utilizzando il foglio incidenze.
B6: CCN OPERATIVO | C6: 2024 | D6: 2025 | E6: 2026 | F6: 2027
B7: Rimanenze | C7: =incidenze!C55 -> 4608814 | D7: =incidenze!D55 -> 4634976.5 | E7: =incidenze!E55 -> 4798127.7 | F7: =incidenze!F55 -> 4967021.8
B8: var rim x-1 | C8: =-573471+141939 -> -431532
B9: Crediti verso clienti | C9: =incidenze!C47 -> 4256399 | D9: =incidenze!D47 -> 4446660 | E9: =incidenze!E47 -> 4645425.7 | F9: =incidenze!F47 -> 4853076.3
B10: Altri crediti | C10: =incidenze!C51 -> 757317 | D10: =incidenze!D51 -> 965508.85 | E10: =incidenze!E51 -> 1035131.8 | F10: =incidenze!F51 -> 1115356.2
B11: Ratei e risconti attivi | C11: 82949 | D11: =incidenze!D58*incidenze!D8 -> 89691.168 | E11: =incidenze!E58*incidenze!E8 -> 93700.363 | F11: =incidenze!F58*incidenze!F8 -> 97888.77
B12: Attivo circolante | C12: =C7+C9+C10+C11 -> 9705479 | D12: =SUM(D7:D11) -> 10136837 | E12: =SUM(E7:E11) -> 10572386 | F12: =SUM(F7:F11) -> 11033343
B13: var. | C13: 0 | D13: =D12-C12 -> 431357.57 | E13: =E12-D12 -> 435549 | F13: =F12-E12 -> 460957.46
B15: Debiti verso fornitori | C15: =incidenze!C62 -> 2274193 | D15: =incidenze!D62 -> 2372164.5 | E15: =incidenze!E62 -> 2455664.6 | F15: =incidenze!F62 -> 2542104
B16: Altri debiti | C16: =incidenze!C65 -> 1126361 | D16: =FONTI!C22 -> 1436005.7 | E16: =FONTI!D22 -> 1539556.2 | F16: =FONTI!E22 -> 1658874.4
B17: Ratei e risconti passivi | C17: =935845 -> 935845 | D17: =incidenze!D67*incidenze!D8 -> 977677.27 | E17: =incidenze!E67*incidenze!E8 -> 1021379.4 | F17: =incidenze!F67*incidenze!F8 -> 1067035.1
B18: Utilizzo fondo TFR | C18: 0 | D18: 0 | E18: 0 | F18: 0
B19: Fondo imposte | C19: 0 | D19: 0 | E19: 0 | F19: 0
B20: Passivo circolante | C20: =SUM(C15:C18) -> 4336399 | D20: =SUM(D15:D18) -> 4785847.4 | E20: =SUM(E15:E18) -> 5016600.3 | F20: =SUM(F15:F18) -> 5268013.5
B21: var. | C21: 0 | D21: =D20-C20 -> 449448.41 | E21: =E20-D20 -> 230752.87 | F21: =F20-E20 -> 251413.22
B23: CCN operativo | C23: =-C20+C12 -> 5369080 | D23: =-D20+D12 -> 5350989.2 | E23: =-E20+E12 -> 5555785.3 | F23: =-F20+F12 -> 5765329.5
B24: var. CCN operativo | C24: 0 | D24: =D23-C23 -> -18090.838 | E24: =E23-D23 -> 204796.13 | F24: =F23-E23 -> 209544.25
C28: Tabella 10B: Individuazione del fabbisogno finanziario a BT
C31: FABBISOGNO FINANZIARIO | D31: 2025 | E31: 2026 | F31: 2027
C32: =B23 -> CCN operativo | D32: =D23 -> 5350989.2 | E32: =E23 -> 5555785.3 | F32: =F23 -> 5765329.5
C33: Immobilizzazioni nette | D33: =INV!N42 -> 8072455.7 | E33: =INV!O42 -> 7288671.2 | F33: =INV!P42 -> 6557438
C35: Fabbisogno fin. | D35: =D32+D33-D34 -> 13423445 | E35: =SUM(E32:E33)-E34 -> 12844457 | F35: =SUM(F32:F33)-F34 -> 12322768
C39: Tabella 10C: Calcolo del volume operativo a BT
C42: VOLUME OPERATIVO | D42: 2025 | E42: 2026 | F42: 2027
C43: crediti commerciali | D43: =D9 -> 4446660 | E43: =E9 -> 4645425.7 | F43: =F9 -> 4853076.3
C44: debiti vs fornitori | D44: =D15 -> 2372164.5 | E44: =E15 -> 2455664.6 | F44: =F15 -> 2542104
C45: scorte | D45: =D7 -> 4634976.5 | E45: =E7 -> 4798127.7 | F45: =F7 -> 4967021.8
C49: Tabella 10D: Misura della durata del ciclo finanziario
C52: CICLO FINANZIARIO | D52: 2025 | E52: 2026 | F52: 2027
C53: giorni medi di permanenza delle scorte in magazzino | D53: =incidenze!D54 -> 111.17593 | E53: =incidenze!E54 -> 111.17593 | F53: =incidenze!F54 -> 111.17593
C54: giorni medi di pagamento dei fornitori | D54: =incidenze!D64 -> 46 | E54: =incidenze!E64 -> 46 | F54: =incidenze!F64 -> 46
C55: giorni medi di incasso clienti | D55: =incidenze!D49 -> 58.517654 | E55: =incidenze!E49 -> 58.517654 | F55: =incidenze!F49 -> 58.517654
C56: ciclo finanziario | D56: =D55-(D54-D53) -> 123.69358 | E56: =E55-(E54-E53) -> 123.69358 | F56: =F55-(F54-F53) -> 123.69358
C58: Dettagli sulla durata del ciclo finanziario | F58: expand for details ↓
F59: +
C61: gg medi di pagamento dei fornitori
C62: gg medi permanenza in magazzino
E63: ciclo finanziario
...

Sheet FONTI
B2: Tabella 8: Proiezione di attività correnti
B4: PROIEZIONE ATT. CORRENTE | C4: 2023 | D4: 2024 | E4: 2025 | F4: 2026 | G4: 2027
B5: Disponibilità liquide | C5: =SUM(C6:C8) -> 891542 | D5: =SUM(D6:D8) -> 242430 | E5: =SUM(E6:E8) -> 184573.18 | F5: =SUM(F6:F8) -> 33419.72 | G5: =SUM(G6:G8) -> 40280.87 | L5: dipende dal tipo di gestione cassa | O5: analisi liquidità | P5: 2024 quick ratio | Q5: =(D5+4256399)/D60 -> 1.325019
B6: Depositi bancari | C6: 891422 | D6: 241919 | E6: =182756.83+21.36 -> 182778.19 | F6: =R43-55.04+20.74 -> 25516.72 | G6: =S43-0.25+20.1 -> 25570.87 | P6: (disp.liq+crediti bt)/debiti imm | R6: -> utilizziamo questo indice come obbiettivo, cerchiamo diavere una capacità sufficiente di ripagare i debiti immediati
B7: Assegni | C7: 0 | D7: 0 | E7: 1700 | F7: 7000 | G7: 14000 | R7: dipende molto dai crediti però
B8: Cassa | C8: 120 | D8: 511 | E8: 94.99 | F8: 903 | G8: 710 | P8: 2024 liq. Imm | Q8: =D5/D60 -> 0.07140177 | R8: -> nel 2024 con le sole disponibilità liquide si sarebbe potuto coprire il 7% di passività
B12: Tabella 8A: Fabbisogno finanziario
B14: FABBISOGNO FINANZIARIO | C14: 2025 | D14: 2026 | E14: 2027
B15: FF netto | C15: =CCN!D35 -> 13423445 | D15: =CCN!E35 -> 12844457 | E15: =CCN!F35 -> 12322768
B16: Debiti v/terzi BT | C16: =G73 -> 2417759.7 | D16: =H73 -> 1349773.2 | E16: =I73 -> 228946.52
B17: Debiti v/terzi ML | C17: =G74 -> 3638932.4 | D17: =H74 -> 2031522.6 | E17: =I74 -> 344583.83
B18: Riserve patrimoniali | C18: =BP!D63 -> 5617287 | D18: =BP!E63 -> 7141058.9 | E18: =BP!F63 -> 8998219.3
B19: check altri debiti | C19: =C15-(C16+C17+C18+C22)-C20-C21 -> 0.0034313193 | D19: =D15-(D16+D17+D18+D22)-D20-D21 -> -0.0044050174 | E19: =E15-(E16+E17+E18+E22)-E20-E21 -> 0.00030418835
B20: Proventi | C20: =C32 -> 129438 | D20: =D32 -> 129438 | E20: =E32 -> 129438
B21: eccesso prov. | C21: 184022.04 | D21: 653107.64 | E21: 962705.51
B22: Altri debiti | C22: =1436005.68 -> 1436005.7 | D22: =1539556.19 -> 1539556.2 | E22: =1658874.35 -> 1658874.4
B26: Tabella 8B: Proventi | G26: expand for details ↓
B27: Spiegazione: | C27: L'impianto fotovoltaico maturato nel 2025 produce energia elettrica. Son disponibili vari approcci ma principalmente c'è ne sono 2: -considerare un valore, ricavo finanziario il saldo tra il consumo di energia elettrica e la produzione (produzione capacità produttiva molto superiore al consumo, anche se considerato capacità produttiva solo giornaliera e in presenza di sole) -considerare il costo di consumo di energia seprato dal ricavo di produzione, provente di vendita extra caratteristico. Nel nostro caso si segue il secondo approccio: capacità produttiva: 399,5 kWP ricavo potenziale a prezzo medio di mercato per zona: 129.438 euro a 0,27 euro kwh rivalutato rispetto a giorni soleggiati annuali per zona e ore solari di produzione:
B31: ALTRI PROVENTI | C31: 2025 | D31: 2026 | E31: 2027
B32: proventi di vendita capacità elettrica | C32: 129438 | D32: 129438 | E32: 129438
B38: Tabella 9: Proiezione finanziamenti
B40: PROIEZIONE INDEBITAMENTI | C40: 2023 | D40: 2024 | E40: 2025 | F40: 2026 | G40: 2027 | O40: LIQ. RICERCATA | P40: 2024 | Q40: 2025 | R40: 2026 | S40: 2027
B41: Debiti pregressi a breve | C41: =C60 -> 3987523 | D41: =D60 -> 3395294 | E41: =G73 -> 2417759.7 | F41: =H73 -> 1349773.2 | G41: =I73 -> 228946.52 | L41: -> ogni anno una parte di debiti a m/l viene traformato in bt, la parte a scadenza. Il debito a B7t può essere rimandato o versato. | O41: debiti v/banche entro | P41: =D60 -> 3395294 | Q41: =E60 -> 1953157.2 | R41: =F60 -> 255510.2 | S41: =G60 -> 255510.2
B42: interesse ipoteticamente noto | C42: =INV!D219+INV!D253+INV!D287+INV!D322+INV!D335 -> 121080.71 | D42: =INV!C348 -> 118261.19 | E42: =E41*E54 -> 109524.52 | F42: =#REF!*F54 -> #REF! | G42: =#REF!*G54 -> #REF! | O42: indice di liquidità immediata | P42: =Q8 -> 0.07140177 | Q42: 0.1 | R42: 0.1 | S42: 0.1
B43: Oneri finanziari BT | C43: =C42 -> 121080.71 | D43: =D42 -> 118261.19 | E43: =E41*E54 -> 109524.52 | F43: =F41*F54 -> 60739.795 | G43: =G41*G54 -> 11195.485 | O43: disponibilità liq. Immediate | P43: =P41*P42 -> 242430 | Q43: =Q41*Q42 -> 195315.72 | R43: =R41*R42 -> 25551.02 | S43: =S41*S42 -> 25551.02
B45: Debiti pregressi a medio/lungo | C45: =C61 -> 6691873 | D45: =D61 -> 5110204 | E45: =G74 -> 3638932.4 | F45: =H74 -> 2031522.6 | G45: =I74 -> 344583.83
B46: Oneri finanziari M/L | C46: =C47-C43 -> 407262.29 | D46: =503404-D43 -> 385142.81 | E46: =E45*E55 -> 160840.81 | F46: =F45*F55 -> 110921.14 | G46: =G45*G55 -> 17905.762
B47: Totale oneri di competenza | C47: 528343 | D47: =D46+D43 -> 503404 | E47: =E46+E43 -> 270365.33 | F47: =F46+F43 -> 171660.93 | G47: =G46+G43 -> 29101.247
B51: Tabella 9A: Rapporto di indebitamento
B53: RAPPORTO INDEBITAMENTO | C53: 2023 | D53: 2024 | E53: 2025 | F53: 2026 | G53: 2027
B54: Rapporto oneri/debito breve | C54: =C43/C41 -> 0.030364893 | D54: =D43/D41 -> 0.034830913 | E54: 0.0453 | F54: 0.045 | G54: 0.0489
B55: Rapporto oneri/debito medio/lungo | C55: =E78 -> 0.049473116 | D55: =F78 -> 0.059185717 | E55: 0.0442 | F55: =E55+0.0104 -> 0.0546 | G55: =_xlfn.FORECAST.LINEAR(G53,C55:F55,C53:F53) -> 0.051963442
E56: https://www.bancaria.it/news/pubblicato-il-rapporto-abi-di-settembre-2025/
B59: Analisi indebitamento | C59: 2023 | D59: 2024 | E59: 2025 | F59: 2026 | G59: 2027
B60: Banche entro | C60: =INV!C372 -> 3987523 | D60: =INV!D372 -> 3395294 | E60: =0.5*D60+0.05*D61 -> 1953157.2 | F60: =0.05*D61 -> 255510.2 | G60: =D61*0.05 -> 255510.2
B61: Banche oltre | C61: =INV!C371 -> 6691873 | D61: =INV!D371 -> 5110204 | E61: =0.9*D61 -> 4599183.6 | F61: =E61-F60 -> 4343673.4 | G61: =F61-G60 -> 4088163.2
B62: Altri fin entro | C62: 435 | D62: 435 | E62: =D62 -> 435 | F62: =E62 -> 435 | G62: =F62 -> 435
B63: Debiti tributari entro | C63: 135216 | D63: 235721 | E63: =TAX!D8+TAX!D12 -> 585090.24 | F63: =TAX!E8+TAX!E12 -> 700688.55 | G63: =TAX!F8+TAX!F12 -> 825126.81
B64: Istituti previdenza entro | C64: 86558 | D64: 70140 | E64: 0 | F64: 0 | G64: 0
B65: Altri debiti entro | C65: 669806 | D65: 820065 | E65: =INV!H190 -> 669806 | F65: =INV!I190 -> 519547 | G65: =INV!J190 -> 369288
...

Sheet TAX
B2: Tabella 18A: Simulazione imposizione fiscale
B4: IMPOSTE | C4: 2024 | D4: 2025 | E4: 2026 | F4: 2027
B5: Aliquota media d'imposta IRES | C5: =incidenze!C36 -> 0.24 | D5: =incidenze!D36 -> 0.24 | E5: =incidenze!E36 -> 0.24 | F5: =incidenze!F36 -> 0.24
B6: utile ante-imposte | C6: =BP!C31 -> 1087201 | D6: =BP!D31 -> 2108862.1 | E6: =BP!E31 -> 2557849 | F6: =BP!F31 -> 3041515.9
B7: Imponibile IRES (utile+costi non deducibili-redditi non imponibili) | C7: =incidenze!C38 -> 1087201 | D7: =incidenze!D38 -> 2108862.1 | E7: =incidenze!E38 -> 2557849 | F7: =incidenze!F38 -> 3041515.9
B8: IRES | C8: =incidenze!C39 -> 260928.24 | D8: =incidenze!D39 -> 506126.91 | E8: =incidenze!E39 -> 613883.76 | F8: =incidenze!F39 -> 729963.81
B10: Aliquota media d'imposta IRAP | C10: =incidenze!C41 -> 0.0268 | D10: =incidenze!D41 -> 0.0268 | E10: =incidenze!E41 -> 0.0268 | F10: =incidenze!F41 -> 0.0268
B11: Imponibile IRAP (A-B) | C11: =incidenze!C42 -> 2279854 | D11: =incidenze!D42 -> 2946393.1 | E11: =incidenze!E42 -> 3238984.5 | F11: =incidenze!F42 -> 3550858.2
B12: IRAP | C12: =incidenze!C43 -> 61100.087 | D12: =incidenze!D43 -> 78963.336 | E12: =incidenze!E43 -> 86804.785 | F12: =incidenze!F43 -> 95163
B16: Tabella 18B: Struttura acconti Irpef per conto dipendenti
D18: RAL | G18: RAL a netto di contributi previdenziali | J18: acconto individuale | M18: acconto totale
B19: CALCOLO ACCONTI IRPEF PER CONTO DIPENDENTI | C19: figure | D19: 2025 | E19: 2026 | F19: 2027 | G19: 2025 | H19: 2026 | I19: 2027 | J19: 2025 | K19: 2026 | L19: 2027 | M19: 2025 | N19: 2026 | O19: 2027
B20: Responsabile di pianificazione | C20: 1 | D20: =HR!F129 -> 39840 | E20: =HR!K129 -> 40812 | F20: =HR!P129 -> 41412 | G20: =D20*0.9081 -> 36178.704 | H20: =E20*0.9081 -> 37061.377 | I20: =F20*0.9081 -> 37606.237 | J20: =IF(G20<28000, G20*$C$39, IF(G20<50000, ((6440+G20-28000)*$C$40), (6440+7700+(G20-50000)*$C$41))) -> 5116.5464 | K20: =IF(H20<28000, H20*$D$39, IF(H20<50000, ((6440+H20-28000)*$D$40), (6440+7700+(H20-50000)*$D$41))) -> 5115.4545 | L20: =IF(I20<28000, I20*$E$39, IF(I20<50000, ((6440+I20-28000)*$E$40), (6440+7700+(I20-50000)*$E$41))) -> 5295.2583 | M20: =J20*$C20 -> 5116.5464 | N20: =K20*$C20 -> 5115.4545 | O20: =L20*$C20 -> 5295.2583
B21: Responsabile alimentare | C21: 1 | D21: =HR!H129 -> 27780 | E21: =HR!M129 -> 28548 | F21: =HR!R129 -> 29040 | G21: =D21*0.9081 -> 25227.018 | H21: =E21*0.9081 -> 25924.439 | I21: =F21*0.9081 -> 26371.224 | J21: =IF(G21<28000, G21*$C$39, IF(G21<50000, ((6440+G21-28000)*$C$40), (6440+7700+(G21-50000)*$C$41))) -> 5802.2141 | K21: =IF(H21<28000, H21*$D$39, IF(H21<50000, ((6440+H21-28000)*$D$40), (6440+7700+(H21-50000)*$D$41))) -> 5962.6209 | L21: =IF(I21<28000, I21*$E$39, IF(I21<50000, ((6440+I21-28000)*$E$40), (6440+7700+(I21-50000)*$E$41))) -> 6065.3815 | M21: =J21*$C21 -> 5802.2141 | N21: =K21*$C21 -> 5962.6209 | O21: =L21*$C21 -> 6065.3815
B22: Operaio | C22: 11 | D22: =HR!E173 -> 22536 | E22: =HR!J173 -> 23100 | F22: =HR!O173 -> 23484 | G22: =D22*0.9081 -> 20464.942 | H22: =E22*0.9081 -> 20977.11 | I22: =F22*0.9081 -> 21325.82 | J22: =IF(G22<28000, G22*$C$39, IF(G22<50000, ((6440+G22-28000)*$C$40), (6440+7700+(G22-50000)*$C$41))) -> 4706.9366 | K22: =IF(H22<28000, H22*$D$39, IF(H22<50000, ((6440+H22-28000)*$D$40), (6440+7700+(H22-50000)*$D$41))) -> 4824.7353 | L22: =IF(I22<28000, I22*$E$39, IF(I22<50000, ((6440+I22-28000)*$E$40), (6440+7700+(I22-50000)*$E$41))) -> 4904.9387 | M22: =J22*$C22 -> 51776.302 | N22: =K22*$C22 -> 53072.088 | O22: =L22*$C22 -> 53954.326
B23: Operai con uso di strumenti tecnici | C23: 5 | D23: =HR!G173 -> 25536 | E23: =HR!L173 -> 26208 | F23: =HR!Q173 -> 26664 | G23: =D23*0.9081 -> 23189.242 | H23: =E23*0.9081 -> 23799.485 | I23: =F23*0.9081 -> 24213.578 | J23: =IF(G23<28000, G23*$C$39, IF(G23<50000, ((6440+G23-28000)*$C$40), (6440+7700+(G23-50000)*$C$41))) -> 5333.5256 | K23: =IF(H23<28000, H23*$D$39, IF(H23<50000, ((6440+H23-28000)*$D$40), (6440+7700+(H23-50000)*$D$41))) -> 5473.8815 | L23: =IF(I23<28000, I23*$E$39, IF(I23<50000, ((6440+I23-28000)*$E$40), (6440+7700+(I23-50000)*$E$41))) -> 5569.123 | M23: =J23*$C23 -> 26667.628 | N23: =K23*$C23 -> 27369.408 | O23: =L23*$C23 -> 27845.615
B24: Addetto al magazzino | C24: 4 | D24: =HR!E217 -> 22296 | E24: =HR!J217 -> 22752 | F24: =HR!O217 -> 26664 | G24: =D24*0.9081 -> 20246.998 | H24: =E24*0.9081 -> 20661.091 | I24: =F24*0.9081 -> 24213.578 | J24: =IF(G24<28000, G24*$C$39, IF(G24<50000, ((6440+G24-28000)*$C$40), (6440+7700+(G24-50000)*$C$41))) -> 4656.8094 | K24: =IF(H24<28000, H24*$D$39, IF(H24<50000, ((6440+H24-28000)*$D$40), (6440+7700+(H24-50000)*$D$41))) -> 4752.051 | L24: =IF(I24<28000, I24*$E$39, IF(I24<50000, ((6440+I24-28000)*$E$40), (6440+7700+(I24-50000)*$E$41))) -> 5569.123 | M24: =J24*$C24 -> 18627.238 | N24: =K24*$C24 -> 19008.204 | O24: =L24*$C24 -> 22276.492
B25: Camionisti | C25: 2 | D25: =HR!G217 -> 23028 | E25: =HR!L217 -> 23496 | F25: =HR!Q217 -> 29040 | G25: =D25*0.9081 -> 20911.727 | H25: =E25*0.9081 -> 21336.718 | I25: =F25*0.9081 -> 26371.224 | J25: =IF(G25<28000, G25*$C$39, IF(G25<50000, ((6440+G25-28000)*$C$40), (6440+7700+(G25-50000)*$C$41))) -> 4809.6972 | K25: =IF(H25<28000, H25*$D$39, IF(H25<50000, ((6440+H25-28000)*$D$40), (6440+7700+(H25-50000)*$D$41))) -> 4907.445 | L25: =IF(I25<28000, I25*$E$39, IF(I25<50000, ((6440+I25-28000)*$E$40), (6440+7700+(I25-50000)*$E$41))) -> 6065.3815 | M25: =J25*$C25 -> 9619.3943 | N25: =K25*$C25 -> 9814.8901 | O25: =L25*$C25 -> 12130.763
B26: Impiegato tecnico | C26: 2 | D26: =HR!E261 -> 25536 | E26: =HR!H261 -> 26208 | F26: =HR!K261 -> 26664 | G26: =D26*0.9081 -> 23189.242 | H26: =E26*0.9081 -> 23799.485 | I26: =F26*0.9081 -> 24213.578 | J26: =IF(G26<28000, G26*$C$39, IF(G26<50000, ((6440+G26-28000)*$C$40), (6440+7700+(G26-50000)*$C$41))) -> 5333.5256 | K26: =IF(H26<28000, H26*$D$39, IF(H26<50000, ((6440+H26-28000)*$D$40), (6440+7700+(H26-50000)*$D$41))) -> 5473.8815 | L26: =IF(I26<28000, I26*$E$39, IF(I26<50000, ((6440+I26-28000)*$E$40), (6440+7700+(I26-50000)*$E$41))) -> 5569.123 | M26: =J26*$C26 -> 10667.051 | N26: =K26*$C26 -> 10947.763 | O26: =L26*$C26 -> 11138.246
B27: Impiegato tecnico-informatico | C27: 1 | D27: =HR!E305 -> 27780 | E27: =HR!H305 -> 28548 | F27: =HR!K305 -> 29040 | G27: =D27*0.9081 -> 25227.018 | H27: =E27*0.9081 -> 25924.439 | I27: =F27*0.9081 -> 26371.224 | J27: =IF(G27<28000, G27*$C$39, IF(G27<50000, ((6440+G27-28000)*$C$40), (6440+7700+(G27-50000)*$C$41))) -> 5802.2141 | K27: =IF(H27<28000, H27*$D$39, IF(H27<50000, ((6440+H27-28000)*$D$40), (6440+7700+(H27-50000)*$D$41))) -> 5962.6209 | L27: =IF(I27<28000, I27*$E$39, IF(I27<50000, ((6440+I27-28000)*$E$40), (6440+7700+(I27-50000)*$E$41))) -> 6065.3815 | M27: =J27*$C27 -> 5802.2141 | N27: =K27*$C27 -> 5962.6209 | O27: =L27*$C27 -> 6065.3815
B28: Impiegato amministrativo-contabile | C28: 2 | D28: =HR!E349 -> 24036 | E28: =HR!H349 -> 24660 | F28: =HR!K349 -> 25080 | G28: =D28*0.9081 -> 21827.092 | H28: =E28*0.9081 -> 22393.746 | I28: =F28*0.9081 -> 22775.148 | J28: =IF(G28<28000, G28*$C$39, IF(G28<50000, ((6440+G28-28000)*$C$40), (6440+7700+(G28-50000)*$C$41))) -> 5020.2311 | K28: =IF(H28<28000, H28*$D$39, IF(H28<50000, ((6440+H28-28000)*$D$40), (6440+7700+(H28-50000)*$D$41))) -> 5150.5616 | L28: =IF(I28<28000, I28*$E$39, IF(I28<50000, ((6440+I28-28000)*$E$40), (6440+7700+(I28-50000)*$E$41))) -> 5238.284 | M28: =J28*$C28 -> 10040.462 | N28: =K28*$C28 -> 10301.123 | O28: =L28*$C28 -> 10476.568
B29: Agente commerciale | C29: 1 | D29: =HR!E393 -> 25536 | E29: =HR!J393 -> 26208 | F29: =HR!O393 -> 26664 | G29: =D29*0.9081 -> 23189.242 | H29: =E29*0.9081 -> 23799.485 | I29: =F29*0.9081 -> 24213.578 | J29: =IF(G29<28000, G29*$C$39, IF(G29<50000, ((6440+G29-28000)*$C$40), (6440+7700+(G29-50000)*$C$41))) -> 5333.5256 | K29: =IF(H29<28000, H29*$D$39, IF(H29<50000, ((6440+H29-28000)*$D$40), (6440+7700+(H29-50000)*$D$41))) -> 5473.8815 | L29: =IF(I29<28000, I29*$E$39, IF(I29<50000, ((6440+I29-28000)*$E$40), (6440+7700+(I29-50000)*$E$41))) -> 5569.123 | M29: =J29*$C29 -> 5333.5256 | N29: =K29*$C29 -> 5473.8815 | O29: =L29*$C29 -> 5569.123
B30: Responsabile commerciale | C30: 1 | D30: =HR!G393 -> 30780 | E30: =HR!L393 -> 31656 | F30: =HR!Q393 -> 32220 | G30: =D30*0.9081 -> 27951.318 | H30: =E30*0.9081 -> 28746.814 | I30: =F30*0.9081 -> 29258.982 | J30: =IF(G30<28000, G30*$C$39, IF(G30<50000, ((6440+G30-28000)*$C$40), (6440+7700+(G30-50000)*$C$41))) -> 6428.8031 | K30: =IF(H30<28000, H30*$D$39, IF(H30<50000, ((6440+H30-28000)*$D$40), (6440+7700+(H30-50000)*$D$41))) -> 2371.6485 | L30: =IF(I30<28000, I30*$E$39, IF(I30<50000, ((6440+I30-28000)*$E$40), (6440+7700+(I30-50000)*$E$41))) -> 2540.6641 | M30: =J30*$C30 -> 6428.8031 | N30: =K30*$C30 -> 2371.6485 | O30: =L30*$C30 -> 2540.6641
B31: Responsabile finanziario | C31: 1 | D31: =HR!E437 -> 39840 | E31: =HR!H437 -> 40812 | F31: =HR!K437 -> 41412 | G31: =D31*0.9081 -> 36178.704 | H31: =E31*0.9081 -> 37061.377 | I31: =F31*0.9081 -> 37606.237 | J31: =IF(G31<28000, G31*$C$39, IF(G31<50000, ((6440+G31-28000)*$C$40), (6440+7700+(G31-50000)*$C$41))) -> 5116.5464 | K31: =IF(H31<28000, H31*$D$39, IF(H31<50000, ((6440+H31-28000)*$D$40), (6440+7700+(H31-50000)*$D$41))) -> 5115.4545 | L31: =IF(I31<28000, I31*$E$39, IF(I31<50000, ((6440+I31-28000)*$E$40), (6440+7700+(I31-50000)*$E$41))) -> 5295.2583 | M31: =J31*$C31 -> 5116.5464 | N31: =K31*$C31 -> 5115.4545 | O31: =L31*$C31 -> 5295.2583
B32: Responsabile esecutivo | C32: 1 | D32: =HR!E481 -> 40548 | E32: =HR!H481 -> 41748 | F32: =HR!K481 -> 42540 | G32: =D32*0.9081 -> 36821.639 | H32: =E32*0.9081 -> 37911.359 | I32: =F32*0.9081 -> 38630.574 | J32: =IF(G32<28000, G32*$C$39, IF(G32<50000, ((6440+G32-28000)*$C$40), (6440+7700+(G32-50000)*$C$41))) -> 5341.5736 | K32: =IF(H32<28000, H32*$D$39, IF(H32<50000, ((6440+H32-28000)*$D$40), (6440+7700+(H32-50000)*$D$41))) -> 5395.9484 | L32: =IF(I32<28000, I32*$E$39, IF(I32<50000, ((6440+I32-28000)*$E$40), (6440+7700+(I32-50000)*$E$41))) -> 5633.2894 | M32: =J32*$C32 -> 5341.5736 | N32: =K32*$C32 -> 5395.9484 | O32: =L32*$C32 -> 5633.2894
L33: TOTALE: | M33: =SUM(M20:M32) -> 166339.5 | N33: =SUM(N20:N32) -> 165911.11 | O33: =SUM(O20:O32) -> 174286.37
B36: Tabella 18C: Aliquote irpef effettive
B38: ALIQUOTE IRPEF | C38: 2025 | D38: 2026 | E38: 2027
B39: fino 28000 | C39: 0.23 | D39: 0.23 | E39: 0.23
B40: da 28.001 a 50.000 | C40: 0.35 | D40: 0.33 | E40: 0.33
B41: oltre 50.0000 | C41: 0.43 | D41: 0.43 | E41: 0.43
B45: Tabella 18D: Debiti verso l'erario a chiusura del bilancio
B47: IMPOSTE A CHIUSURA DEL BILANCIO | C47: 2024 | D47: 2025 | E47: 2026 | F47: 2027
B48: Erario c/IVA | C48: =(BP!C6*0.22*1/12)-('COSTI DI GESTIONE & BEP'!D11+'COSTI DI GESTIONE & BEP'!D43+'COSTI DI GESTIONE & BEP'!D39)*(1/12)*0.22 -> 71672.81 | D48: =(BP!D6*0.22*1/12)-('COSTI DI GESTIONE & BEP'!E11+'COSTI DI GESTIONE & BEP'!E43+'COSTI DI GESTIONE & BEP'!E39)*(1/12)*0.22 -> 85854.286 | E48: =(BP!E6*0.22*1/12)-('COSTI DI GESTIONE & BEP'!F11+'COSTI DI GESTIONE & BEP'!F43+'COSTI DI GESTIONE & BEP'!F39)*(1/12)*0.22 -> 92045.246 | F48: =(BP!F6*0.22*1/12)-('COSTI DI GESTIONE & BEP'!G11+'COSTI DI GESTIONE & BEP'!G43+'COSTI DI GESTIONE & BEP'!G39)*(1/12)*0.22 -> 99178.905
B49: Debito: Acconto IRPEF per conto dipendenti | D49: =1/12*M33 -> 13861.625 | E49: =1/12*N33 -> 13825.925 | F49: =1/12*O33 -> 14523.864
D51: Si tratta del pagamento dell'ultima mensilità

Sheet incidenze
B2: Tabella 11: Ipotesi e incidenze previsionali | H2: expand for details ↓
H3: +
B4: Spiegazione: | C4: Individuate varie voci di costi rispetto al bilancio consuntivo del 2024. Ciascuna voce ha avuto progressione di crescita/diminuzione o stabilità rispetto ai fattori presi in considerazione, visibile espandendo il banner laterale alla destra della tabella.
B6: IPOTESI PREVISIONALI | C6: 2024 | D6: 2025 | E6: 2026 | F6: 2027 | H6: Benchmark di settore
B7: CONTO ECONOMICO
B8: Ricavi | C8: ='REVENUE MODEL'!S34 -> 21463379 | D8: ='REVENUE MODEL'!J34 -> 22422792 | E8: ='REVENUE MODEL'!K34 -> 23425091 | F8: ='REVENUE MODEL'!L34 -> 24472192
B9: Costo del venduto / Ricavi | C9: ='COSTI DI GESTIONE & BEP'!D11/incidenze!C8 -> 0.70497413 | D9: ='COSTI DI GESTIONE & BEP'!E11/incidenze!D8 -> 0.67864076 | E9: ='COSTI DI GESTIONE & BEP'!F11/incidenze!E8 -> 0.67246953 | F9: ='COSTI DI GESTIONE & BEP'!G11/incidenze!F8 -> 0.66635442 | G9: → | H9: ='D. Benchmark di settore'!P15 -> 0.74703255
B10: Costi per servizi / Ricavi | C10: ='COSTI DI GESTIONE & BEP'!D39/incidenze!C8 -> 0.1128539 | D10: ='COSTI DI GESTIONE & BEP'!E39/incidenze!D8 -> 0.11248422 | E10: ='COSTI DI GESTIONE & BEP'!F39/incidenze!E8 -> 0.11317699 | F10: ='COSTI DI GESTIONE & BEP'!G39/incidenze!F8 -> 0.1125637 | G10: → | H10: ='D. Benchmark di settore'!Q15 -> 0.55114031
